<mujoco model="ant">
  <compiler angle="degree" coordinate="local" inertiafromgeom="true"/>
  <option timestep="0.01" iterations="4" />
  <custom>
    <!-- brax custom params -->
    <!-- <numeric data="0 0 0.55 1.0 0.0 0.0 0.0 0.0 1.0 0.0 -1.0 0.0 -1.0 0.0 1.0 0.0 0.0" name="init_qpos"/> -->
    <numeric data="1000" name="constraint_limit_stiffness"/>
    <numeric data="4000" name="constraint_stiffness"/>
    <numeric data="10" name="constraint_ang_damping"/>
    <numeric data="20" name="constraint_vel_damping"/>
    <numeric data="0.5" name="joint_scale_pos"/>
    <numeric data="0.2" name="joint_scale_ang"/>
    <numeric data="0.0" name="ang_damping"/>
    <numeric data="1" name="spring_mass_scale"/>
    <numeric data="1" name="spring_inertia_scale"/>
    <numeric data="15" name="solver_maxls"/>
  </custom>
  <default>
    <joint armature="1" damping="1" limited="true"/>
    <geom contype="0" conaffinity="0" condim="3" density="5.0" friction="1 0.5 0.5"/>
  </default>
  <asset>
    <texture builtin="gradient" height="100" rgb1="1 1 1" rgb2="0 0 0" type="skybox" width="100"/>
    <texture builtin="flat" height="1278" mark="cross" markrgb="1 1 1" name="texgeom" random="0.01" rgb1="0.8 0.6 0.4" rgb2="0.8 0.6 0.4" type="cube" width="127"/>
    <texture builtin="checker" height="100" name="texplane" rgb1="0 0 0" rgb2="0.8 0.8 0.8" type="2d" width="100"/>
    <material name="MatPlane" reflectance="0.5" shininess="1" specular="1" texrepeat="60 60" texture="texplane"/>
    <material name="geom" texture="texgeom" texuniform="true"/>
  </asset>
  <worldbody>
    <light cutoff="100" diffuse="1 1 1" dir="-0 0 -1.3" directional="true" exponent="1" pos="0 0 1.3" specular=".1 .1 .1"/>
    <geom conaffinity="1" condim="3" material="MatPlane" name="floor" pos="0 0 0" size="100 100 40" type="plane"/>
    <body name="torso" pos="0 0 0.75">
      <camera name="track" mode="trackcom" pos="0 -3 0.3" xyaxes="1 0 0 0 0 1"/>
      <geom name="torso_geom" pos="0 0 0" size="0.25" type="sphere" conaffinity="1" contype="1"/>
      <!-- <joint armature="0" damping="0" limited="false" margin="0.01" name="root" pos="0 0 0" type="free"/> -->

      <joint name="obj_slidex" type="slide" pos="0 0 0" axis="1 0 0" range="-100 100" damping="0.0"/>
      <joint name="obj_slidey" type="slide" pos="0 0 0" axis="0 1 0" range="-100 100" damping="0.0"/>
    </body>


    <body name="target" pos="0 0 0.01">
        <joint armature="0" axis="1 0 0" damping="0" limited="true" name="target_x" pos="0 0 0" range="-100 100" stiffness="0" type="slide"/>
        <joint armature="0" axis="0 1 0" damping="0" limited="true" name="target_y" pos="0 0 0" range="-100 100" stiffness="0" type="slide"/>
        <geom conaffinity="0" contype="0" name="target" pos="0 0 0" size=".9" type="sphere"  mass="1.0"/>
    </body>
  </worldbody>
  <actuator>
    <motor name="move_x" joint="obj_slidex" gear="5 0 0"/>
    <motor name="move_y" joint="obj_slidey" gear="5 0 0"/>
  </actuator>
</mujoco>
